Workbook

Sheet README
A1: CORSA Jakarta Flagship – Financial Model v0.2
A2: Preliminary – most inputs are placeholders to be validated.
A4: Note from Jonas | B4: I created this Financial model to give me a general overview of all the components to take into account. I'm using it to. However, even if most data are sourced, I'm currently working on checking all the numbers and data, and verify the accuracy of the finidngs. Many data need to be discussed with the Pillar 1 team, and I'm waiting for their inputs to adjust the model.
A6: Purpose | B6: Test whether a 120–180 m² CORSA flagship in Jakarta works commercially, what it costs, whether CHF 200k is enough and which assumptions matter most.
A7: How to use | B7: 1) Pick scenario in Inputs!D4. 2) Edit blue cells only (Inputs, Rent_Data, Menu, Staffing, CAPEX unit costs, Revenue dwell times). 3) Read Dashboard, Scenarios, Sensitivity, MonteCarlo.
A8: Colour code | B8: Blue text = hard-coded input · Black = formula · Green = link to another sheet · Yellow fill = key assumption · Light-green fill = key output.
A9: Currency | B9: Model runs in IDR; CHF shown at the Inputs FX rate. Menu prices are NET of the 10% restaurant tax (PBJT), which is passed through to guests.
A10: Sheet map | B10: Dashboard → Inputs → Rent_Data → Location → Menu → Revenue → Staffing → OPEX → CAPEX → Funding → Scenarios → PnL_Monthly → Annual → Sensitivity → MonteCarlo → Sources → Research_Tracker → Methods
A11: Scenario logic | B11: Conservative = fewer guests, lower spend, higher costs/rent, longer ramp-up. Optimistic = the reverse. Scenarios sheet calculates all three in parallel (steady state); PnL_Monthly runs the active one month by month.
A12: Biggest early finding | B12: Foreign-owned PT PMA rules (IDR 2.5bn paid-up ≈ CHF 115k, IDR 10bn investment plan ≈ CHF 460k per KBLI) may matter more for the CHF 200k question than the CAPEX itself – verify with a lawyer.
A13: Status | B13: v0.2 – structure complete, numbers indicative, every input traced to a source or marked as an assumption. See Research_Tracker for what to validate before 22 Oct.
A14: Sources (v0.2) | B14: Added 8 Oct 2026: 32 new sources (S46–S77) and a source trail on every sheet – per-row columns in Inputs (I, K, L), Staffing (K–M), CAPEX (K–M), Menu (O–Q), and a 'Sources & calculation basis' table at the bottom of every other sheet (MonteCarlo: top right).
A15: v0.6 (16 Oct 2026) | B15: CAPEX (Rent) completed: per-item financing route (buy / finance lease / rental / sponsor), BFI-based lease maths, provider directory, Buy-vs-Lease summary; new switch Inputs!H4 (1 = Buy, 2 = Lease) feeds Funding, PnL, Scenarios, Annual, Dashboard. Sources S83–S104.

Sheet Dashboard
A1: CORSA Jakarta Flagship – Dashboard
A2: Live outputs for the ACTIVE scenario (change it in Inputs!D4). All figures are preliminary estimates.
A3: Not from Jonas: | B3: This sheet will make more sense once many more data will be confirmed and scenario tested
B4: But the KPIs are relevant in my opinion
A5: Active scenario | B5: =Inputs!$E$4 -> Base
A6: CAPEX mode | B6: =Inputs!$I$4 -> Lease – CAPEX (Rent)
A7: Key question (brief) | B7: IDR | C7: CHF
A8: Total investment requirement | B8: =CHOOSE(Inputs!$H$4,'CAPEX (Buy)'!$H$37,'CAPEX (Rent)'!$H$40) -> 4.2662461e+09 | C8: =B8/Inputs!$H$10 -> 197511.39
A9: Founder equity | B9: =Funding!$B$8 -> 4320000000 | C9: =B9/Inputs!$H$10 -> 200000
A10: Funding gap (+) / surplus (−) | B10: =Funding!$B$9 -> -53753870 | C10: =B10/Inputs!$H$10 -> -2488.6051
A11: Bank loan needed | B11: =Funding!$B$10 -> 0 | C11: =B11/Inputs!$H$10 -> 0
A12: Mature monthly revenue (year-1 prices) | B12: =Scenarios!$F$13 -> 735630000 | C12: =B12/Inputs!$H$10 -> 34056.944
A13: Steady-state monthly EBITDA | B13: =Scenarios!$F$34 -> 1.3478627e+08 | C13: =B13/Inputs!$H$10 -> 6240.1051
A14: Break-even revenue per trading day | B14: =Scenarios!$F$43 -> 16761712 | C14: =B14/Inputs!$H$10 -> 776.00518
A15: Year-1 revenue (with ramp-up) | B15: =Annual!$C$5 -> 7295392080 | C15: =B15/Inputs!$H$10 -> 337749.63
A16: Year-1 EBITDA | B16: =Annual!$C$11 -> 7.3026459e+08 | C16: =B16/Inputs!$H$10 -> 33808.546
A17: Year-3 EBITDA | B17: =Annual!$E$11 -> 0 | C17: =B17/Inputs!$H$10 -> 0
A18: Lowest cash balance over 60 months | B18: =MIN(PnL_Monthly!$C$49:$BJ$49) -> 7.9481373e+08 | C18: =B18/Inputs!$H$10 -> 36796.932
A19: NPV of 5-year project cash flows | B19: =Annual!$C$31 -> -3.185886e+09 | C19: =B19/Inputs!$H$10 -> -147494.72
A20: Break-even guests per day | B20: =Scenarios!$F$45 -> 136.71312
A21: Mature guests per day (model) | B21: =Scenarios!$F$6 -> 200
A22: EBITDA margin at maturity | B22: =Scenarios!$F$35 -> 0.18322563
A23: Prime cost % (COGS + staff) | B23: =Scenarios!$F$39 -> 0.51941666
A24: Occupancy cost % (rent + SC) | B24: =Scenarios!$F$40 -> 0.051349481
A25: Payback month (full model, incl. ramp-up) | B25: =IF(MIN(PnL_Monthly!$C$53:$BJ$53)=0,"> 60 months",MIN(PnL_Monthly!$C$53:$BJ$53)) -> > 60 months
A26: Project IRR (5 yrs incl. terminal value) | B26: =Annual!$C$30 -> -0.46909486
A27: PT PMA paid-up capital check | B27: =Funding!$B$23 -> OK – equity covers paid-up capital
A28: Seats | B28: =Revenue!$C$5 -> 60
A29: Equipment lease/rental/sponsor payments per month (months 1–36) | B29: =IF(Inputs!$H$4=2,'CAPEX (Rent)'!$H$47,0) -> 18483150 | C29: =B29/Inputs!$H$10 -> 855.70137
B30: Scenario comparison (steady state) | C30: Conservative | D30: Base | E30: Optimistic
A31: Revenue / month (IDR) | B31: =Scenarios!$C$13 -> 481770000 | C31: =Scenarios!$D$13 -> 735630000 | D31: =Scenarios!$E$13 -> 1083805000
A32: EBITDA / month (IDR) | B32: =Scenarios!$C$34 -> -1.0789767e+08 | C32: =Scenarios!$D$34 -> 1.3478627e+08 | D32: =Scenarios!$E$34 -> 4.116417e+08
A33: EBITDA margin | B33: =Scenarios!$C$35 -> -0.22396096 | C33: =Scenarios!$D$35 -> 0.18322563 | D33: =Scenarios!$E$35 -> 0.37981159
A34: Break-even revenue / day (IDR) | B34: =Scenarios!$C$43 -> 22950907 | C34: =Scenarios!$D$43 -> 16761712 | D34: =Scenarios!$E$43 -> 14180295
A35: Break-even guests / day | B35: =Scenarios!$C$45 -> 221.52005 | C35: =Scenarios!$D$45 -> 136.71312 | D35: =Scenarios!$E$45 -> 100.09112
A36: Total investment (CHF) | B36: =Scenarios!$C$54 -> 314583.94 | C36: =Scenarios!$D$54 -> 197511.39 | D36: =Scenarios!$E$54 -> 159628.48
A37: Gap vs CHF 200k equity (CHF) | B37: =Scenarios!$C$55 -> 114583.94 | C37: =Scenarios!$D$55 -> -2488.6051 | D37: =Scenarios!$E$55 -> -40371.523
A38: Simple payback (years) | B38: =Scenarios!$C$56 -> never | C38: =Scenarios!$D$56 -> 3.3816169 | D38: =Scenarios!$E$56 -> 0.93217547
A40: MODEL CHECKS
A41: Scenario engine = CAPEX sheet | B41: =Scenarios!$F$58 -> OK
...

Sheet Inputs
A1: Inputs & Scenario Assumptions
A2: Every assumption lives here. Edit blue cells (columns E–G). Column H = active scenario. Column I = source IDs (Sources sheet), column K = how each value was calculated, column L = evidence status (green = sourced/derived, yellow = partly sourced, orange = assumption to validate).
C4: ACTIVE SCENARIO (1 = Conservative, 2 = Base, 3 = Optimistic) → | D4: 2 | E4: =CHOOSE($D$4,"Conservative","Base","Optimistic") -> Base | F4: CAPEX MODE (1 = Buy, 2 = Lease/sponsor) → | H4: 2 | I4: =CHOOSE($H$4,"Buy – CAPEX (Buy)","Lease – CAPEX (Rent)") -> Lease – CAPEX (Rent)
A5: Note from Jonas: | B5: These Inputs and scenarios have not been carefully reviewed yet. This sheet will be more relevant once other assumptions will be confirmed or infirmed
B6: Regarding the seasonality, the impact of Ramadan and seasons on the scheduling of consumptions as well as the quantity must be assessed (culture and society?)
A8: Key | B8: Category | C8: Parameter | D8: Unit | E8: Conservative | F8: Base | G8: Optimistic | H8: ACTIVE | I8: Source ID(s) & key facts (see Sources sheet) | J8: Confidence | K8: How the value was calculated from the source | L8: Evidence status
A9: GENERAL & MACRO
A10: fx | B10: Macro | C10: FX rate (IDR per 1 CHF) | D10: IDR/CHF | E10: 20500 | F10: 21600 | G10: 22500 | H10: =CHOOSE($D$4,E10,F10,G10) -> 21600 | I10: S16 (CHF/IDR spot ~21,580; 30-day avg 21,640; 90-day range 21,423–22,518) | J10: H | K10: Base 21,600 = 30-day average 21,640 rounded. Conservative 20,500 ≈ 5% below the 90-day low (weaker CHF→IDR conversion of equity). Optimistic 22,500 ≈ 90-day high 22,518. | L10: Derived from sources
A11: open_date | B11: Timing | C11: Opening month (first month of trading) | D11: date | E11: 46569 | F11: 46569 | G11: 46569 | H11: =CHOOSE($D$4,E11,F11,G11) -> 46569 | I11: S65 (PT PMA setup), S10 (fit-out); brief | J11: L | K11: Oct 2026 + ~3 months company setup/licensing (S65) + 3–4 months lease search & fit-out + buffer ≈ Jul 2027. Timeline estimate, not a sourced figure. | L11: Assumption – validate
A12: days | B12: Timing | C12: Trading days per month | D12: days | E12: 30 | F12: 30 | G12: 30 | H12: =CHOOSE($D$4,E12,F12,G12) -> 30 | I12: Team assumption (7-day operation); Ramadan/Lebaran handled by seasonality (S58) | J12: M | K12: 30 trading days per month = 7-day opening. Closure days around Idul Fitri are captured through the Mar seasonality index, not here. | L12: Assumption – validate
A13: price_inc | B13: Macro | C13: Menu price increase p.a. | D13: % | E13: 0.03 | F13: 0.04 | G13: 0.05 | H13: =CHOOSE($D$4,E13,F13,G13) -> 0.04 | I13: S18 (CPI 3.28% yoy Sep 2026; volatile food 5.03%; core 2.84%) | J13: M | K13: Base 4% sits between headline CPI 3.28% and volatile-food inflation 5.03% (menu costs track food). Conservative 3% ≈ CPI (cannot pass on food inflation). Optimistic 5% ≈ volatile-food inflation. | L13: Derived from sources
A14: infl | B14: Macro | C14: Opex inflation p.a. | D14: % | E14: 0.045 | F14: 0.035 | G14: 0.03 | H14: =CHOOSE($D$4,E14,F14,G14) -> 0.035 | I14: S18 (CPI 3.28%), S17 (BI target 2.5% ±1) | J14: M | K14: Base 3.5% = CPI 3.28% rounded up / top of BI band. Conservative 4.5% = 1 pp above band. Optimistic 3.0% = band mid-point + 0.5 pp. | L14: Derived from sources
A15: wage_g | B15: Macro | C15: Wage growth p.a. | D15: % | E15: 0.07 | F15: 0.062 | G15: 0.05 | H15: =CHOOSE($D$4,E15,F15,G15) -> 0.062 | I15: S04 (Jakarta UMP 2026 +6.17% vs 2025) | J15: M | K15: Base 6.2% = latest UMP increase 6.17%. Conservative 7%, optimistic 5% = ±1 pp around it. | L15: Derived from sources
A16: cit | B16: Tax | C16: Corporate income tax rate | D16: % | E16: 0.22 | F16: 0.22 | G16: 0.22 | H16: =CHOOSE($D$4,E16,F16,G16) -> 0.22 | I16: S15 (PT PMA not eligible for 0.5% MSME final tax); UU HPP – CIT 22% | J16: M | K16: Statutory corporate rate 22% applied to all scenarios. | L16: Sourced
A17: pbjt | B17: Tax | C17: Restaurant tax PBJT (charged on top of menu prices) | D17: % | E17: 0.1 | F17: 0.1 | G17: 0.1 | H17: =CHOOSE($D$4,E17,F17,G17) -> 0.1 | I17: S13 (Jakarta PBJT food & beverage 10%), S03 | J17: H | K17: 10% charged on top of net menu prices and passed to the government → excluded from revenue. | L17: Sourced
A18: vat | B18: Tax | C18: Non-recoverable VAT on CAPEX & services | D18: % | E18: 0.11 | F18: 0.11 | G18: 0.11 | H18: =CHOOSE($D$4,E18,F18,G18) -> 0.11 | I18: S03 (restaurants collect PBJT, not VAT → input VAT not creditable); VAT rate 11% | J18: M | K18: 11% statutory VAT on CAPEX/services treated as a cost because it cannot be reclaimed. | L18: Sourced
A19: LOCATION & SPACE
A20: district | B20: Location | C20: Selected district (1 SCBD, 2 Senopati main road, 3 Senopati side streets, 4 Kuningan, 5 Kemang, 6 PIK) | D20: # | E20: 2 | F20: 2 | G20: 2 | H20: =CHOOSE($D$4,E20,F20,G20) -> 2 | I20: Location sheet (scores from S20–S29, S46) | J20: - | K20: Decision input: 2 = Senopati main road (highest weighted score with acceptable rent). | L20: Decision / policy
A21: sqm | B21: Space | C21: Usable floor area (ground floor focus) | D21: m² | E21: 150 | F21: 150 | G21: 150 | H21: =CHOOSE($D$4,E21,F21,G21) -> 150 | I21: Brief (120–180 m², ground floor) | J21: - | K21: 150 m² = mid-point of the brief's 120–180 m² range. | L21: Decision / policy
A22: gfa_factor | B22: Space | C22: Paid surface ÷ trading surface (non-trading space you still pay for) | D22: x | E22: 1.2 | F22: 1 | G22: 1 | H22: =CHOOSE($D$4,E22,F22,G22) -> 1 | I22: Rent_Data (v0.5: listings filtered to 100–200 m² of total rented surface) | J22: L | K22: Rent_Data now holds units of 100–200 m² total surface (all floors), matching the brief's 120–180 m², so rent = rate × 150 m² with no upper-floor gross-up (base/optimistic 1.0). Conservative 1.2 = paying ~30 m² of stairs/storage/non-trading space (e.g. a 180 m² unit for 150 m² used). Team estimate. | L22: Partly sourced
A23: foh_share | B23: Space | C23: Dining area share of usable area | D23: % | E23: 0.6 | F23: 0.6 | G23: 0.6 | H23: =CHOOSE($D$4,E23,F23,G23) -> 0.6 | I23: S35 (Toast: ~60/40 dining/kitchen split) | J23: M | K23: 60% of 150 m² = 90 m² dining area. | L23: Sourced
A24: sqm_seat | B24: Space | C24: m² of dining area per seat | D24: m² | E24: 1.5 | F24: 1.5 | G24: 1.5 | H24: =CHOOSE($D$4,E24,F24,G24) -> 1.5 | I24: S35 (12–15 sq ft/seat ≈ 1.1–1.4 m²) | J24: M | K24: 1.5 m²/seat = top of the S35 range (1.4 m²) + comfort margin for a flagship → 90 m² / 1.5 = 60 seats. | L24: Derived from sources
A25: rent_sqm | B25: Rent | C25: Base rent (IDR per m² GFA per month) | D25: IDR | E25: =INDEX(Location!$E$8:$E$13,$H$20) -> 351857.87 | F25: =INDEX(Location!$D$8:$D$13,$H$20) -> 251828.12 | G25: =INDEX(Location!$C$8:$C$13,$H$20) -> 205161.38 | H25: =CHOOSE($D$4,E25,F25,G25) -> 251828.12 | I25: Location → Rent_Data (S20–S26 listings) | J25: L | K25: Linked: Optimistic = P25, Base = median, Conservative = P75 of asking rents per m² of rented surface (100–200 m² units) for the selected district. Senopati main road uses the side-street × premium fallback while it has <3 listings. | L25: Derived from sources
A26: sc_sqm | B26: Rent | C26: Service charge / CAM (IDR per m² per month) | D26: IDR | E26: =INDEX(Location!$G$8:$G$13,$H$20) -> 0 | F26: =INDEX(Location!$G$8:$G$13,$H$20) -> 0 | G26: =INDEX(Location!$G$8:$G$13,$H$20) -> 0 | H26: =CHOOSE($D$4,E26,F26,G26) -> 0 | I26: Location col G; S27 (mall SC IDR 154k/m²/mo) | J26: L | K26: Linked: street ruko = 0 (owner pays building costs); mall/podium units use the Location sheet estimate (anchored on S27). | L26: Derived from sources
A27: rent_grossup | B27: Rent | C27: Rent gross-up for 10% PPh 4(2) if landlord quotes net | D27: % | E27: 0.111 | F27: 0 | G27: 0 | H27: =CHOOSE($D$4,E27,F27,G27) -> 0 | I27: S14 (PPh 4(2) final tax 10% on gross rent, withheld by corporate tenant) | J27: M | K27: If the landlord quotes rent net of tax, cost = net ÷ 0.9 → +11.1%. Conservative assumes net quote; base/optimistic assume gross quote (0%). | L27: Derived from sources
A28: rent_esc | B28: Rent | C28: Rent escalation p.a. | D28: % | E28: 0.08 | F28: 0.06 | G28: 0.05 | H28: =CHOOSE($D$4,E28,F28,G28) -> 0.06 | I28: S18 (CPI 3.28%); S28/S29 (vacancy tightening, F&B demand) | J28: L | K28: Base 6% ≈ CPI + ~3 pp for a tightening prime market. No published Jakarta ruko renewal-uplift statistic found → ask 2 brokers (Research_Tracker). | L28: Assumption – validate
A29: prepay_m | B29: Rent | C29: Rent paid upfront (months per payment block) | D29: months | E29: 24 | F29: 12 | G29: 12 | H29: =CHOOSE($D$4,E29,F29,G29) -> 12 | I29: S20/S21 listings & research notes (ruko leases min. 12 months, 1–2 yrs paid upfront) | J29: M | K29: Base 12 months paid upfront per block; conservative 24 months. | L29: Partly sourced
A30: deposit_m | B30: Rent | C30: Security deposit (months of rent) | D30: months | E30: 3 | F30: 2 | G30: 1 | H30: =CHOOSE($D$4,E30,F30,G30) -> 2 | I30: No public source found – market practice to confirm with brokers | J30: L | K30: Security deposit 2 months (base). Validate in broker interviews. | L30: Assumption – validate
A31: fitout_m | B31: Rent | C31: Paid rent months during fit-out (before opening) | D31: months | E31: 3 | F31: 2 | G31: 1 | H31: =CHOOSE($D$4,E31,F31,G31) -> 2 | I31: No public source found – negotiation point | J31: L | K31: Base: 2 months rent paid during fit-out; optimistic 1 (rent-free period negotiated). | L31: Assumption – validate
A32: REVENUE AT MATURITY (per trading day, before ramp-up & seasonality)
A33: cov_morning | B33: Revenue | C33: Guests – morning 07–11 (coffee, breakfast) | D33: guests/day | E33: 35 | F33: 45 | G33: 55 | H33: =CHOOSE($D$4,E33,F33,G33) -> 45 | I33: S46 Volume_Proxy (busiest in-zone comparables ≈ 53–67 guests/day base, 106–134 high); S43 (Fore ≈ IDR 13m sales/store/day) | J33: L | K33: Daypart split of a 200-guest day: morning 45 / lunch 75 / afternoon 35 / dinner 45. Cross-check: busiest in-zone pasta venues ≈ 53–67 guests/day at 100 guests/review (134 at 200/review); Fore Coffee IDR 1.5tn ÷ 316 stores ÷ 365 ≈ IDR 13m/day per store. CORSA base needs 200 → above any measured pasta comparable; this is the most important assumption to validate with field counts. | L33: Assumption – validate
A34: tkt_morning | B34: Revenue | C34: Avg net spend – morning | D34: IDR/guest | E34: 55000 | F34: 65000 | G34: 75000 | H34: =CHOOSE($D$4,E34,F34,G34) -> 65000 | I34: S31 (latte 45–52k, pastry), Menu sheet prices | J34: M | K34: Latte 50k + 40% pastry attach × 38k ≈ 65k. | L34: Derived from sources
A35: cov_lunch | B35: Revenue | C35: Guests – lunch 11–15 | D35: guests/day | E35: 60 | F35: 75 | G35: 95 | H35: =CHOOSE($D$4,E35,F35,G35) -> 75 | I35: See cov_morning (S46, S43) | J35: L | K35: 75 guests = largest daypart (office lunch, SCBD/Senopati). Same evidence caveat as above. | L35: Assumption – validate
A36: tkt_lunch | B36: Revenue | C36: Avg net spend – lunch (pasta + drink) | D36: IDR/guest | E36: 110000 | F36: 120000 | G36: 135000 | H36: =CHOOSE($D$4,E36,F36,G36) -> 120000 | I36: S46 (in-zone pasta venue median avg ~133k); S33/S34; Menu sheet | J36: M | K36: Pasta ~98k + 50% drink attach × ~45k ≈ 120k. Note: S46 shows in-zone pasta at ~133k → price headroom. | L36: Derived from sources
A37: cov_aft | B37: Revenue | C37: Guests – afternoon 15–18 | D37: guests/day | E37: 25 | F37: 35 | G37: 45 | H37: =CHOOSE($D$4,E37,F37,G37) -> 35 | I37: See cov_morning (S46, S43) | J37: L | K37: 35 guests (coffee/snack). No direct evidence. | L37: Assumption – validate
A38: tkt_aft | B38: Revenue | C38: Avg net spend – afternoon | D38: IDR/guest | E38: 60000 | F38: 70000 | G38: 80000 | H38: =CHOOSE($D$4,E38,F38,G38) -> 70000 | I38: S31, Menu sheet | J38: L | K38: Coffee/functional drink ~50k + 50% snack attach × ~40k ≈ 70k. | L38: Derived from sources
A39: cov_dinner | B39: Revenue | C39: Guests – dinner 18–22 | D39: guests/day | E39: 35 | F39: 45 | G39: 60 | H39: =CHOOSE($D$4,E39,F39,G39) -> 45 | I39: See cov_morning; S46 Weekday_Pattern (weekend ≈ 1.45× weekday) | J39: L | K39: 45 guests average incl. weekend uplift. No direct evidence. | L39: Assumption – validate
A40: tkt_dinner | B40: Revenue | C40: Avg net spend – dinner | D40: IDR/guest | E40: 125000 | F40: 140000 | G40: 150000 | H40: =CHOOSE($D$4,E40,F40,G40) -> 140000 | I40: S46, S33/S34 (casual Italian 100–200k pp), Menu sheet | J40: L | K40: Pasta ~105k + 60% drink × 45k + 20% dessert × 55k ≈ 143k → 140k. | L40: Derived from sources
A41: del_orders | B41: Revenue | C41: Delivery orders per day (GoFood/GrabFood/ShopeeFood) | D41: orders/day | E41: 15 | F41: 25 | G41: 35 | H41: =CHOOSE($D$4,E41,F41,G41) -> 25 | I41: S30 (delivery market USD 5.4bn; Grab 47% / Gojek 35% / Shopee 18%) | J41: L | K41: 25 orders/day is a volume assumption; S30 only sizes the market. | L41: Assumption – validate
A42: del_tkt | B42: Revenue | C42: Avg delivery order value (gross, app price) | D42: IDR/order | E42: 100000 | F42: 115000 | G42: 130000 | H42: =CHOOSE($D$4,E42,F42,G42) -> 115000 | I42: S46 (delivery prices ~15.6% above dine-in net); S32 vs S31 | J42: M | K42: ~100k dine-in basket × 1.156 ≈ 115k gross app value. | L42: Derived from sources
...

Sheet Rent_Data
A1: Rent Evidence – Asking Rents from Listing Portals (accessed 6–8 Oct 2026) – units of 100–200 m²
A2: Only units with 100–200 m² of rented surface are kept (all floors, any format), per the brief's 120–180 m². IDR per m² of rented surface per month; asking prices – deals usually 5–15% lower.
A3: Jonas: | B3: I built this sheet to gather existing offers in both Tier 1 and Tier 2 locations and have an overview. | M3: Columns M–T: exact address as advertised, Google Maps link, link to the individual ad, listing ID, advertiser, ad date, verification note.
B4: I voluntarily choose a range from 100 to 200sqm to get more locations (more accurate quantitative data) and avoid rejectance of surface that my be inexact in the offers.
B5: These are selected available locations to give an idea of types of available surfaces and their prices . If @sam you have some contacts with agencies, I'd love to have a look and add their offers to this sheet
A7: # | B7: District | C7: Location / street | D7: Type | E7: Asking rent (IDR) | F7: Period | G7: Monthly rent (IDR) | H7: Surface m² (all floors) | I7: Floors | J7: IDR / m² / month | K7: Source | L7: Note | M7: Exact address / building (as advertised) | N7: Map | O7: Listing (click to open) | P7: Listing URL | Q7: Listing ID | R7: Advertiser / agent | S7: Ad date | T7: Verification 8 Oct 2026
A8: 3 | B8: SCBD | C8: Pacific Century Tower (rooftop F&B space) | D8: F&B space | E8: 95000000 | F8: month | G8: =IF(F8="year",E8/12,E8) -> 95000000 | H8: 191 | J8: =G8/H8 -> 497382.2 | K8: S23 | L8: Excl. VAT & service charge | M8: Pacific Century Place (PCP) Tower, SCBD Lot 10, Jakarta Selatan – rooftop | N8: =HYPERLINK("https://www.google.com/maps/search/?api=1&query=Pacific+Century+Place+SCBD+Jakarta","Google Maps") -> Google Maps | O8: =HYPERLINK("https://www.rumah123.com/en/property/jakarta-selatan-scbd/disewakan-space-utk-resto-bar-rooftop-di-pacific-century-tower-scbd-csr3740301/","Open ad") -> Open ad | P8: https://www.rumah123.com/en/property/jakarta-selatan-scbd/disewakan-space-utk-resto-bar-rooftop-di-pacific-century-tower-scbd-csr3740301/ | Q8: csr3740301 | R8: Zwitsa Bella Ratu (independent) | S8: Updated 28 Oct 2025 | T8: Confirmed. Same space also advertised by Sangga Buana (2 duplicate ads). Excl. VAT & service charge.
A9: 5 | B9: SCBD | C9: Equity Tower | D9: Office (reference) | E9: 60160000 | F9: month | G9: =IF(F9="year",E9/12,E9) -> 60160000 | H9: 188 | J9: =G9/H9 -> 320000 | K9: S22 | L9: Office tower – reference only | M9: Equity Tower, SCBD Lot 9, Jl. Jend. Sudirman Kav. 52-53, Jakarta Selatan | N9: =HYPERLINK("https://www.google.com/maps/search/?api=1&query=Equity+Tower+SCBD+Jakarta","Google Maps") -> Google Maps | O9: =HYPERLINK("https://www.rumah123.com/en/rent/jakarta-selatan/scbd/commercial-space/","Open results page") -> Open results page | P9: https://www.rumah123.com/en/rent/jakarta-selatan/scbd/commercial-space/ | Q9: not found | R9: Putera Frans – Century21 Rich Realty (on results page) | S9: not shown | T9: Individual ad not found (unverified candidates on Rumah123: ofr4180086, ofr4456549). Office tower – reference only.
A11: 6 | B11: Senopati main road | C11: Jl. Suryo – 3rd floor only | D11: Upper floor in building | E11: 520000000 | F11: year | G11: =IF(F11="year",E11/12,E11) -> 43333333 | H11: 150 | I11: 1 | J11: =G11/H11 -> 288888.89 | K11: S78 | L11: Upper floor, not street level | M11: Jl. Suryo (= Jl. Senopati), Kebayoran Baru, Jakarta Selatan | N11: =HYPERLINK("https://www.google.com/maps/search/?api=1&query=" & SUBSTITUTE(M11," ","+"),"Google Maps") -> Google Maps | O11: =HYPERLINK(P11,"Open results page") -> Open results page | P11: https://www.rumah123.com/en/rent/jakarta-selatan/senopati/shophouse/ | Q11: results page only | R11: Efendi Tobing – BAA Homes | S11: updated c. 4 Oct 2026 | T11: Seen on the Rumah123 results page only. Only 1 main-road listing → Location uses fallback until ≥3 (289k/m² vs fallback 267k: consistent).
A13: 7 | B13: Senopati side streets | C13: Wolter Monginsidi | D13: Ruko | E13: 29000000 | F13: month | G13: =IF(F13="year",E13/12,E13) -> 29000000 | H13: 185 | I13: 4 | J13: =G13/H13 -> 156756.76 | K13: S20 | M13: Jl. Wolter Monginsidi, Kebayoran Baru, Jakarta Selatan | N13: =HYPERLINK("https://www.google.com/maps/search/?api=1&query=Jl.+Wolter+Monginsidi+Kebayoran+Baru+Jakarta","Google Maps") -> Google Maps | O13: =HYPERLINK("https://www.flokq.com/sewa-ruko-jakarta/ruko/RKRbd0","Open ad") -> Open ad | P13: https://www.flokq.com/sewa-ruko-jakarta/ruko/RKRbd0 | Q13: RKRbd0 | R13: not shown on ad | S13: not shown | T13: Confirmed (nego).
A14: 8 | B14: Senopati side streets | C14: Wolter Monginsidi | D14: Ruko | E14: 29200000 | F14: month | G14: =IF(F14="year",E14/12,E14) -> 29200000 | H14: 195 | I14: 3 | J14: =G14/H14 -> 149743.59 | K14: S20 | M14: Jl. Wolter Monginsidi, Kebayoran Baru, Jakarta Selatan | N14: =HYPERLINK("https://www.google.com/maps/search/?api=1&query=Jl.+Wolter+Monginsidi+Kebayoran+Baru+Jakarta","Google Maps") -> Google Maps | O14: =HYPERLINK("https://www.flokq.com/sewa-ruko-jakarta/ruko/RKRfe7","Open ad") -> Open ad | P14: https://www.flokq.com/sewa-ruko-jakarta/ruko/RKRfe7 | Q14: RKRfe7 | R14: not shown on ad | S14: not shown | T14: Confirmed (nego).
A15: 9 | B15: Senopati side streets | C15: Wolter Monginsidi | D15: Ruko | E15: 16700000 | F15: month | G15: =IF(F15="year",E15/12,E15) -> 16700000 | H15: 160 | I15: 2 | J15: =G15/H15 -> 104375 | K15: S20 | M15: Near Jl. Wolter Monginsidi, Kebayoran Baru, Jakarta Selatan | N15: =HYPERLINK("https://www.google.com/maps/search/?api=1&query=Jl.+Wolter+Monginsidi+Kebayoran+Baru+Jakarta","Google Maps") -> Google Maps | O15: =HYPERLINK("https://www.flokq.com/sewa-ruko-jakarta/ruko/RKR37e","Open ad") -> Open ad | P15: https://www.flokq.com/sewa-ruko-jakarta/ruko/RKR37e | Q15: RKR37e | R15: not shown on ad | S15: not shown | T15: Confirmed (nego).
A16: 10 | B16: Senopati side streets | C16: Wijaya | D16: Ruko | E16: 37500000 | F16: month | G16: =IF(F16="year",E16/12,E16) -> 37500000 | H16: 112 | I16: 2 | J16: =G16/H16 -> 334821.43 | K16: S20 | M16: Jl. Wijaya, Kebayoran Baru, Jakarta Selatan | N16: =HYPERLINK("https://www.google.com/maps/search/?api=1&query=Jl.+Wijaya+I+Kebayoran+Baru+Jakarta","Google Maps") -> Google Maps | O16: =HYPERLINK("https://www.flokq.com/sewa-ruko-jakarta/ruko/RKR485","Open ad") -> Open ad | P16: https://www.flokq.com/sewa-ruko-jakarta/ruko/RKR485 | Q16: RKR485 | R16: not shown on ad | S16: not shown | T16: Confirmed. Twin ad RKR100 (same price/m², 4 floors).
A17: 11 | B17: Senopati side streets | C17: Haji Nawi | D17: Ruko | E17: 12500000 | F17: month | G17: =IF(F17="year",E17/12,E17) -> 12500000 | H17: 150 | I17: 2 | J17: =G17/H17 -> 83333.333 | K17: S20 | M17: Jl. Haji Nawi, Gandaria, Jakarta Selatan | N17: =HYPERLINK("https://www.google.com/maps/search/?api=1&query=Jl.+Haji+Nawi+Jakarta+Selatan","Google Maps") -> Google Maps | O17: =HYPERLINK("https://www.flokq.com/sewa-ruko-jakarta/ruko/RKR7b7","Open ad") -> Open ad | P17: https://www.flokq.com/sewa-ruko-jakarta/ruko/RKR7b7 | Q17: RKR7b7 | R17: not shown on ad | S17: not shown | T17: Price shown on results page only; ad page says 'nego'.
A18: 12 | B18: Senopati side streets | C18: Haji Nawi Raya | D18: Ruko | E18: 23000000 | F18: month | G18: =IF(F18="year",E18/12,E18) -> 23000000 | H18: 143 | I18: 2 | J18: =G18/H18 -> 160839.16 | K18: S20 | M18: Jl. Haji Nawi Raya, Gandaria, Jakarta Selatan | N18: =HYPERLINK("https://www.google.com/maps/search/?api=1&query=Jl.+Haji+Nawi+Raya+Jakarta+Selatan","Google Maps") -> Google Maps | O18: =HYPERLINK("https://www.flokq.com/sewa-ruko-jakarta/ruko/RKR678","Open ad") -> Open ad | P18: https://www.flokq.com/sewa-ruko-jakarta/ruko/RKR678 | Q18: RKR678 | R18: not shown on ad | S18: not shown | T18: Confirmed.
A19: 13 | B19: Senopati side streets | C19: Kebayoran Baru | D19: Ruko | E19: 18800000 | F19: month | G19: =IF(F19="year",E19/12,E19) -> 18800000 | H19: 160 | I19: 2 | J19: =G19/H19 -> 117500 | K19: S20 | M19: Kebayoran Baru, near Treasury Tower & Pacific Century Place, Jakarta Selatan | N19: =HYPERLINK("https://www.google.com/maps/search/?api=1&query=Pacific+Century+Place+SCBD+Jakarta","Google Maps") -> Google Maps | O19: =HYPERLINK("https://www.flokq.com/sewa-ruko-jakarta/ruko/RKR6fb","Open ad") -> Open ad | P19: https://www.flokq.com/sewa-ruko-jakarta/ruko/RKR6fb | Q19: RKR6fb | R19: not shown on ad | S19: c. Apr 2025 (photo filename) | T19: Confirmed (nego).
A20: 14 | B20: Senopati side streets | C20: Kebayoran Baru | D20: Ruko | E20: 16700000 | F20: month | G20: =IF(F20="year",E20/12,E20) -> 16700000 | H20: 160 | I20: 3 | J20: =G20/H20 -> 104375 | K20: S20 | M20: Kebayoran Baru, Jakarta Selatan (no street given) | N20: =HYPERLINK("https://www.google.com/maps/search/?api=1&query=Kebayoran+Baru+Jakarta+Selatan","Google Maps") -> Google Maps | O20: =HYPERLINK("https://www.flokq.com/sewa-ruko-jakarta/ruko/RKRcae","Open ad") -> Open ad | P20: https://www.flokq.com/sewa-ruko-jakarta/ruko/RKRcae | Q20: RKRcae | R20: not shown on ad | S20: c. Mar 2025 (photo filename) | T20: Confirmed (nego). Location vague.
A21: 15 | B21: Senopati side streets | C21: Kyai Maja | D21: Ruko | E21: 14500000 | F21: month | G21: =IF(F21="year",E21/12,E21) -> 14500000 | H21: 193 | I21: 3 | J21: =G21/H21 -> 75129.534 | K21: S20 | M21: Jl. Kyai Maja, Kebayoran Baru, Jakarta Selatan | N21: =HYPERLINK("https://www.google.com/maps/search/?api=1&query=Jl.+Kyai+Maja+Jakarta+Selatan","Google Maps") -> Google Maps | O21: =HYPERLINK("https://www.flokq.com/sewa-ruko-jakarta/ruko/RKR927","Open ad") -> Open ad | P21: https://www.flokq.com/sewa-ruko-jakarta/ruko/RKR927 | Q21: RKR927 | R21: not shown on ad | S21: not shown | T21: Confirmed (nego).
A22: 16 | B22: Senopati side streets | C22: Cipaku | D22: Ruko | E22: 9000000 | F22: month | G22: =IF(F22="year",E22/12,E22) -> 9000000 | H22: 105 | I22: 2 | J22: =G22/H22 -> 85714.286 | K22: S20 | M22: Jl. Cipaku, Kebayoran Baru (near Treasury Tower / Pacific Century Place), Jakarta Selatan | N22: =HYPERLINK("https://www.google.com/maps/search/?api=1&query=" & SUBSTITUTE(M22," ","+"),"Google Maps") -> Google Maps | O22: =HYPERLINK(P22,"Open ad") -> Open ad | P22: https://www.flokq.com/sewa-ruko-jakarta/ruko/RKRb4b | Q22: RKRb4b | R22: not shown | S22: not shown | T22: Added 8 Oct 2026. Price from Flokq results page (ad says nego). Cipaku is at the edge of the Senopati area.
A24: 17 | B24: Kuningan | C24: Jl. HR Rasuna Said | D24: Ruko | E24: 35000000 | F24: month | G24: =IF(F24="year",E24/12,E24) -> 35000000 | H24: 110 | I24: 2 | J24: =G24/H24 -> 318181.82 | K24: S24 | M24: Jl. HR Rasuna Said, Kuningan, Jakarta Selatan | N24: =HYPERLINK("https://www.google.com/maps/search/?api=1&query=Jl.+HR+Rasuna+Said+Kuningan+Jakarta","Google Maps") -> Google Maps | O24: =HYPERLINK("https://www.flokq.com/sewa-ruko-jakarta/ruko/RKR3de","Open ad") -> Open ad | P24: https://www.flokq.com/sewa-ruko-jakarta/ruko/RKR3de | Q24: RKR3de | R24: not shown on ad | S24: not shown | T24: Confirmed (nego).
A25: 18 | B25: Kuningan | C25: Epicentrum Walk (Epiwalk) – ex-restaurant | D25: Shophouse in mall complex | E25: 330000000 | F25: year | G25: =IF(F25="year",E25/12,E25) -> 27500000 | H25: 110 | I25: 2 | J25: =G25/H25 -> 250000 | K25: S79 | L25: Ex-resto, furnished, 24h mall access | M25: Epicentrum Walk, Jl. HR Rasuna Said, Kuningan, Jakarta Selatan | N25: =HYPERLINK("https://www.google.com/maps/search/?api=1&query=" & SUBSTITUTE(M25," ","+"),"Google Maps") -> Google Maps | O25: =HYPERLINK(P25,"Open ad") -> Open ad | P25: https://www.rumah123.com/properti/jakarta-pusat-menteng/disewakan-ex-resto-di-epiwalk-rasuna-said-kuningan-shr9910999/ | Q25: shr9910999 | R25: Gido – GadingPro Menteng | S25: c. Aug 2026 | T25: Added 8 Oct 2026 from results page; ad page would not open – confirm with agent.
A27: 19 | B27: Kemang | C27: Benda Kemang | D27: Ruko | E27: 20800000 | F27: month | G27: =IF(F27="year",E27/12,E27) -> 20800000 | H27: 170 | I27: 1 | J27: =G27/H27 -> 122352.94 | K27: S25 | M27: Jl. Benda / Kemang, Jakarta Selatan | N27: =HYPERLINK("https://www.google.com/maps/search/?api=1&query=Jl.+Benda+Kemang+Jakarta+Selatan","Google Maps") -> Google Maps | O27: =HYPERLINK("https://www.flokq.com/sewa-ruko-jakarta/ruko/RKR422","Open ad") -> Open ad | P27: https://www.flokq.com/sewa-ruko-jakarta/ruko/RKR422 | Q27: RKR422 | R27: not shown on ad | S27: not shown | T27: Confirmed (rounded '20,8 juta', nego).
A28: 20 | B28: Kemang | C28: Kemang | D28: Ruko | E28: 29000000 | F28: month | G28: =IF(F28="year",E28/12,E28) -> 29000000 | H28: 170 | I28: 1 | J28: =G28/H28 -> 170588.24 | K28: S25 | M28: Kemang, Jakarta Selatan (no street given) | N28: =HYPERLINK("https://www.google.com/maps/search/?api=1&query=Kemang+Jakarta+Selatan","Google Maps") -> Google Maps | O28: =HYPERLINK("https://www.flokq.com/sewa-ruko-jakarta/ruko/RKR3c0","Open ad") -> Open ad | P28: https://www.flokq.com/sewa-ruko-jakarta/ruko/RKR3c0 | Q28: RKR3c0 | R28: not shown on ad | S28: not shown | T28: Confirmed. Near-twin of row 44 (RKR653).
A29: 21 | B29: Kemang | C29: Kemang Raya | D29: Ruko | E29: 50000000 | F29: month | G29: =IF(F29="year",E29/12,E29) -> 50000000 | H29: 120 | I29: 4 | J29: =G29/H29 -> 416666.67 | K29: S25 | M29: Jl. Kemang Raya, near Kinderfield School, Jakarta Selatan | N29: =HYPERLINK("https://www.google.com/maps/search/?api=1&query=Jl.+Kemang+Raya+Jakarta+Selatan","Google Maps") -> Google Maps | O29: =HYPERLINK("https://www.flokq.com/sewa-ruko-jakarta/ruko/RKR71d","Open ad") -> Open ad | P29: https://www.flokq.com/sewa-ruko-jakarta/ruko/RKR71d | Q29: RKR71d | R29: not shown on ad | S29: not shown | T29: Confirmed (nego).
A30: 22 | B30: Kemang | C30: Kemang Raya | D30: Ruko | E30: 29000000 | F30: month | G30: =IF(F30="year",E30/12,E30) -> 29000000 | H30: 170 | I30: 1 | J30: =G30/H30 -> 170588.24 | K30: S25 | M30: Jl. Kemang Raya, Jakarta Selatan | N30: =HYPERLINK("https://www.google.com/maps/search/?api=1&query=Jl.+Kemang+Raya+Jakarta+Selatan","Google Maps") -> Google Maps | O30: =HYPERLINK("https://www.flokq.com/sewa-ruko-jakarta/ruko/RKR653","Open ad") -> Open ad | P30: https://www.flokq.com/sewa-ruko-jakarta/ruko/RKR653 | Q30: RKR653 | R30: not shown on ad | S30: not shown | T30: Confirmed. Floors not stated in ad.
A31: 23 | B31: Kemang | C31: Kemang | D31: Ruko | E31: 16600000 | F31: month | G31: =IF(F31="year",E31/12,E31) -> 16600000 | H31: 128 | I31: 2 | J31: =G31/H31 -> 129687.5 | K31: S25 | M31: Kemang, Jakarta Selatan (no street; ad body wrongly says 'Kemang, Bogor') | N31: =HYPERLINK("https://www.google.com/maps/search/?api=1&query=Kemang+Jakarta+Selatan","Google Maps") -> Google Maps | O31: =HYPERLINK("https://www.flokq.com/sewa-ruko-jakarta/ruko/RKR545","Open ad") -> Open ad | P31: https://www.flokq.com/sewa-ruko-jakarta/ruko/RKR545 | Q31: RKR545 | R31: not shown on ad | S31: not shown | T31: Confirmed (nego).
A32: 24 | B32: Kemang | C32: Jl. Benda Raya | D32: Ruko | E32: 25000000 | F32: month | G32: =IF(F32="year",E32/12,E32) -> 25000000 | H32: 110 | I32: 1 | J32: =G32/H32 -> 227272.73 | K32: S25 | M32: Jl. Benda Raya No. 1, Kemang, Jakarta Selatan | N32: =HYPERLINK("https://www.google.com/maps/search/?api=1&query=Jl.+Benda+Raya+No.+1+Kemang+Jakarta+Selatan","Google Maps") -> Google Maps | O32: =HYPERLINK("https://www.flokq.com/sewa-ruko-jakarta/ruko/RKR7fd","Open ad") -> Open ad | P32: https://www.flokq.com/sewa-ruko-jakarta/ruko/RKR7fd | Q32: RKR7fd | R32: not shown on ad | S32: not shown | T32: Confirmed. Identical twin ad RKR961. Ad says 2 floors (model: 1).
A33: 25 | B33: Kemang | C33: Kemang Utara | D33: Ruko | E33: 25000000 | F33: month | G33: =IF(F33="year",E33/12,E33) -> 25000000 | H33: 200 | I33: 2 | J33: =G33/H33 -> 125000 | K33: S25 | M33: Jl. Kemang Utara, Jakarta Selatan | N33: =HYPERLINK("https://www.google.com/maps/search/?api=1&query=Jl.+Kemang+Utara+Jakarta+Selatan","Google Maps") -> Google Maps | O33: =HYPERLINK("https://www.flokq.com/sewa-ruko-jakarta/ruko/RKR5f6","Open ad") -> Open ad | P33: https://www.flokq.com/sewa-ruko-jakarta/ruko/RKR5f6 | Q33: RKR5f6 | R33: not shown on ad | S33: not shown | T33: Confirmed (nego).
A34: 26 | B34: Kemang | C34: Kemang Timur Raya | D34: Ruko | E34: 15000000 | F34: month | G34: =IF(F34="year",E34/12,E34) -> 15000000 | H34: 180 | I34: 2 | J34: =G34/H34 -> 83333.333 | K34: S25 | M34: Jl. Kemang Timur Raya, near Pasar Kemang, Jakarta Selatan | N34: =HYPERLINK("https://www.google.com/maps/search/?api=1&query=Jl.+Kemang+Timur+Raya+Jakarta+Selatan","Google Maps") -> Google Maps | O34: =HYPERLINK("https://www.flokq.com/sewa-ruko-jakarta/ruko/RKR729","Open ad") -> Open ad | P34: https://www.flokq.com/sewa-ruko-jakarta/ruko/RKR729 | Q34: RKR729 | R34: not shown on ad | S34: not shown | T34: Confirmed (nego).
A35: 27 | B35: Kemang | C35: Kemang Raya | D35: Ruko | E35: 29200000 | F35: month | G35: =IF(F35="year",E35/12,E35) -> 29200000 | H35: 200 | I35: 3 | J35: =G35/H35 -> 146000 | K35: S25 | M35: Jl. Kemang Raya, Jakarta Selatan | N35: =HYPERLINK("https://www.google.com/maps/search/?api=1&query=Jl.+Kemang+Raya+Jakarta+Selatan","Google Maps") -> Google Maps | O35: =HYPERLINK("https://www.flokq.com/sewa-ruko-jakarta/ruko/RKR5b3","Open ad") -> Open ad | P35: https://www.flokq.com/sewa-ruko-jakarta/ruko/RKR5b3 | Q35: RKR5b3 | R35: not shown on ad | S35: not shown | T35: Confirmed (nego).
A36: 28 | B36: Kemang | C36: Kemang Raya | D36: Ruko | E36: 23330000 | F36: month | G36: =IF(F36="year",E36/12,E36) -> 23330000 | H36: 200 | I36: 2 | J36: =G36/H36 -> 116650 | K36: S80 | M36: Jl. Kemang Raya, Mampang Prapatan, Jakarta Selatan | N36: =HYPERLINK("https://www.google.com/maps/search/?api=1&query=" & SUBSTITUTE(M36," ","+"),"Google Maps") -> Google Maps | O36: =HYPERLINK(P36,"Open ad") -> Open ad | P36: https://www.pinhome.id/disewa/ruko-sekunder/unit/disewakan-ruko-lokasi-strategis-di-kemang-raya-1 | Q36: I-78337 | R36: Indah – Agen Kantor Properti | S36: not shown (photos c. 2022) | T36: Added 8 Oct 2026; confirmed on ad. May be stale – confirm availability.
A37: 29 | B37: Kemang | C37: Bangka – 1-floor F&B unit | D37: Ruko (single level) | E37: 350000000 | F37: year | G37: =IF(F37="year",E37/12,E37) -> 29166667 | H37: 200 | I37: 1 | J37: =G37/H37 -> 145833.33 | K37: S81 | L37: Min. 2 yrs; no alcohol / non-halal | M37: Bangka, Mampang Prapatan (Kemang), Jakarta Selatan | N37: =HYPERLINK("https://www.google.com/maps/search/?api=1&query=" & SUBSTITUTE(M37," ","+"),"Google Maps") -> Google Maps | O37: =HYPERLINK(P37,"Open ad") -> Open ad | P37: https://kiosrumah.com/iklan/ruko/disewakan-ruko-kemang-1-lantai-untuk-f-b-bangka-mampang-prapat/26185 | Q37: TRK173 | R37: Roby – Century21 | S37: not shown (photos c. Nov 2024) | T37: Added 8 Oct 2026; confirmed on ad, marketed for F&B. Confirm availability.
A38: 30 | B38: Kemang | C38: Kemang Raya 10 – business space | D38: Commercial space | E38: 30000000 | F38: month | G38: =IF(F38="year",E38/12,E38) -> 30000000 | H38: 130 | J38: =G38/H38 -> 230769.23 | K38: S82 | M38: Jl. Kemang Raya, Jakarta Selatan | N38: =HYPERLINK("https://www.google.com/maps/search/?api=1&query=" & SUBSTITUTE(M38," ","+"),"Google Maps") -> Google Maps | O38: =HYPERLINK(P38,"Open results page") -> Open results page | P38: https://www.rumah123.com/en/rent/jakarta-selatan/kemang/commercial-space/ | Q38: results page only | R38: not shown | S38: not shown | T38: Added 8 Oct 2026 from results page; floors unknown.
A40: 31 | B40: PIK | C40: Jl. Elang Laut, PIK | D40: Ruko | E40: 175000000 | F40: year | G40: =IF(F40="year",E40/12,E40) -> 14583333 | H40: 160 | I40: 3.5 | J40: =G40/H40 -> 91145.833 | K40: S26 | M40: Jl. Elang Laut, PIK 1, Jakarta Utara | N40: =HYPERLINK("https://www.google.com/maps/search/?api=1&query=Jl.+Elang+Laut+PIK+Jakarta+Utara","Google Maps") -> Google Maps | O40: =HYPERLINK("https://www.brighton.co.id/cari-properti/view/ruko-3-5-lantai-di-elang-laut-pantai-indah-kapuk","Open ad") -> Open ad | P40: https://www.brighton.co.id/cari-properti/view/ruko-3-5-lantai-di-elang-laut-pantai-indah-kapuk | Q40: 091826-BRIM00005 | R40: Andy Andreas – Brighton Impact Jelambar (probable) | S40: 05 Oct 2026 | T40: Confirmed. Description says LB 76.5 (inconsistent with 160).
A41: 32 | B41: PIK | C41: Stanford Boulevard, PIK 2 | D41: Ruko | E41: 300000000 | F41: year | G41: =IF(F41="year",E41/12,E41) -> 25000000 | H41: 197 | J41: =G41/H41 -> 126903.55 | K41: S26 | M41: Ruko Stanford Boulevard, unit A6, PIK 2, Jakarta Utara | N41: =HYPERLINK("https://www.google.com/maps/search/?api=1&query=Stanford+Boulevard+PIK+2","Google Maps") -> Google Maps | O41: =HYPERLINK("https://www.brighton.co.id/cari-properti/view/ruko-pik-2-stanford-boulevard-hadap-jalan-utama","Open ad") -> Open ad | P41: https://www.brighton.co.id/cari-properti/view/ruko-pik-2-stanford-boulevard-hadap-jalan-utama | Q41: 311026-PROBS00022 | R41: not shown on ad | S41: 02 Oct 2026 | T41: Confirmed. 285m/yr on 2-yr lease, 275m on 3-yr; deposit 35m.
A42: 33 | B42: PIK | C42: Pasadena Walk, PIK 2 | D42: Ruko | E42: 80000000 | F42: year | G42: =IF(F42="year",E42/12,E42) -> 6666666.7 | H42: 141 | J42: =G42/H42 -> 47281.324 | K42: S26 | M42: Pasadena Walk, PIK 2, Jakarta Utara | N42: =HYPERLINK("https://www.google.com/maps/search/?api=1&query=Pasadena+Walk+PIK+2","Google Maps") -> Google Maps | O42: =HYPERLINK("https://www.brighton.co.id/disewa/ruko/jakarta-utara/pantai-indah-kapuk","Open results page") -> Open results page | P42: https://www.brighton.co.id/disewa/ruko/jakarta-utara/pantai-indah-kapuk | Q42: not found | R42: not shown on ad | S42: not shown | T42: NOT FOUND – individual ad not traceable (removed or on page 2+). Treat as unverified.
C45: Reference: Jakarta mall average (Colliers Q4 2024, S27): rent IDR 564,400 + service charge IDR 154,035 per m²/month
A48: SOURCES & CALCULATION BASIS – Rent_Data
A49: Figure / cells | D49: Value used (live) | E49: Source ID(s) → Sources sheet | H49: How the figure was derived from the source | M49: Evidence status
A50: Asking rent, period, m², floors (cols E, F, H, I) | D50: — | E50: Per row in col K: S20–S26, S78–S82 | H50: Copied from each listing as advertised (accessed 6–8 Oct 2026). Surface m² = total rented surface of the unit, all floors (LB for a ruko). | M50: Sourced
...

Sheet Location
A1: Location Economics – District Comparison
A2: Rent statistics come from Rent_Data. Scores and demand index are judgement inputs (blue) – replace with field observation (footfall counts, competitor mapping).
A3: Note from Jonas: | B3: Georaphical information would be really interesting to assess the areas.
B4: The choice of criteria as well as their weight may be edited depending on goals and findings from group1
A5: Criteria weights → | I5: 0.2 | J5: 0.2 | K5: 0.2 | L5: 0.2 | M5: 0.1 | N5: 0.1 | O5: =SUM(I5:N5) -> 1
A7: District | B7: Tier | C7: Rent P25 (IDR/m²/mo) | D7: Rent median | E7: Rent P75 | F7: n | G7: Service charge IDR/m²/mo | H7: Demand index (Senopati=1) | I7: Footfall | J7: Office density | K7: Target-customer fit | L7: Visibility / street | M7: Competition (5=low) | N7: Access (MRT etc.) | O7: Weighted score (/5) | P7: Monthly rent+SC for model unit | Q7: Est. monthly revenue | R7: Occupancy cost % of revenue | S7: Est. EBITDA / month | T7: Break-even revenue / day | U7: Rent cap @12% → max monthly rent | V7: Main-road premium × (used while n < 3)
A8: SCBD | B8: 1 | C8: =PERCENTILE(Rent_Data!$J$8:$J$9,0.25) -> 364345.55 | D8: =MEDIAN(Rent_Data!$J$8:$J$9) -> 408691.1 | E8: =PERCENTILE(Rent_Data!$J$8:$J$9,0.75) -> 453036.65 | F8: =COUNT(Rent_Data!$J$8:$J$9) -> 2 | G8: 120000 | H8: 1.1 | O8: =SUMPRODUCT(I8:N8,$I$5:$N$5) -> 0 | P8: =(D8*(1+Inputs!$H$27)+G8)*Inputs!$H$21*Inputs!$H$22 -> 79303665 | Q8: =Scenarios!$F$13*H8 -> 8.09193e+08 | R8: =P8/Q8 -> 0.0980034 | S8: =Q8*Scenarios!$F$24-(Scenarios!$F$32+P8) -> 1.3585215e+08 | T8: =(Scenarios!$F$32+P8)/Scenarios!$F$24/Inputs!$H$12 -> 19152452 | U8: =0.12*Q8 -> 97103160
A9: Senopati main road | B9: 1 | C9: =IF($F$9>=3,PERCENTILE(Rent_Data!$J$11:$J$11,0.25),C10*$V$9) -> 205161.38 | D9: =IF($F$9>=3,MEDIAN(Rent_Data!$J$11:$J$11),D10*$V$9) -> 251828.12 | E9: =IF($F$9>=3,PERCENTILE(Rent_Data!$J$11:$J$11,0.75),E10*$V$9) -> 351857.87 | F9: =COUNT(Rent_Data!$J$11:$J$11) -> 1 | G9: 0 | H9: 1 | O9: =SUMPRODUCT(I9:N9,$I$5:$N$5) -> 0 | P9: =(D9*(1+Inputs!$H$27)+G9)*Inputs!$H$21*Inputs!$H$22 -> 37774219 | Q9: =Scenarios!$F$13*H9 -> 735630000 | R9: =P9/Q9 -> 0.051349481 | S9: =Q9*Scenarios!$F$24-(Scenarios!$F$32+P9) -> 1.3478627e+08 | T9: =(Scenarios!$F$32+P9)/Scenarios!$F$24/Inputs!$H$12 -> 16761712 | U9: =0.12*Q9 -> 88275600 | V9: 2.27
A10: Senopati side streets | B10: 1 | C10: =PERCENTILE(Rent_Data!$J$13:$J$22,0.25) -> 90379.464 | D10: =MEDIAN(Rent_Data!$J$13:$J$22) -> 110937.5 | E10: =PERCENTILE(Rent_Data!$J$13:$J$22,0.75) -> 155003.47 | F10: =COUNT(Rent_Data!$J$13:$J$22) -> 10 | G10: 0 | H10: 0.9 | O10: =SUMPRODUCT(I10:N10,$I$5:$N$5) -> 0 | P10: =(D10*(1+Inputs!$H$27)+G10)*Inputs!$H$21*Inputs!$H$22 -> 16640625 | Q10: =Scenarios!$F$13*H10 -> 662067000 | R10: =P10/Q10 -> 0.025134352 | S10: =Q10*Scenarios!$F$24-(Scenarios!$F$32+P10) -> 1.1332454e+08 | T10: =(Scenarios!$F$32+P10)/Scenarios!$F$24/Inputs!$H$12 -> 15545107 | U10: =0.12*Q10 -> 79448040
A11: Kuningan | B11: 1 | C11: =PERCENTILE(Rent_Data!$J$24:$J$25,0.25) -> 267045.45 | D11: =MEDIAN(Rent_Data!$J$24:$J$25) -> 284090.91 | E11: =PERCENTILE(Rent_Data!$J$24:$J$25,0.75) -> 301136.36 | F11: =COUNT(Rent_Data!$J$24:$J$25) -> 2 | G11: 50000 | H11: 0.9 | O11: =SUMPRODUCT(I11:N11,$I$5:$N$5) -> 0 | P11: =(D11*(1+Inputs!$H$27)+G11)*Inputs!$H$21*Inputs!$H$22 -> 50113636 | Q11: =Scenarios!$F$13*H11 -> 662067000 | R11: =P11/Q11 -> 0.075692696 | S11: =Q11*Scenarios!$F$24-(Scenarios!$F$32+P11) -> 79851526 | T11: =(Scenarios!$F$32+P11)/Scenarios!$F$24/Inputs!$H$12 -> 17472059 | U11: =0.12*Q11 -> 79448040
A12: Kemang | B12: 2 | C12: =PERCENTILE(Rent_Data!$J$27:$J$38,0.25) -> 124338.24 | D12: =MEDIAN(Rent_Data!$J$27:$J$38) -> 145916.67 | E12: =PERCENTILE(Rent_Data!$J$27:$J$38,0.75) -> 184759.36 | F12: =COUNT(Rent_Data!$J$27:$J$38) -> 12 | G12: 0 | H12: 0.85 | O12: =SUMPRODUCT(I12:N12,$I$5:$N$5) -> 0 | P12: =(D12*(1+Inputs!$H$27)+G12)*Inputs!$H$21*Inputs!$H$22 -> 21887500 | Q12: =Scenarios!$F$13*H12 -> 625285500 | R12: =P12/Q12 -> 0.03500401 | S12: =Q12*Scenarios!$F$24-(Scenarios!$F$32+P12) -> 86779999 | T12: =(Scenarios!$F$32+P12)/Scenarios!$F$24/Inputs!$H$12 -> 15847156 | U12: =0.12*Q12 -> 75034260
A13: PIK | B13: 2 | C13: =PERCENTILE(Rent_Data!$J$40:$J$42,0.25) -> 69213.579 | D13: =MEDIAN(Rent_Data!$J$40:$J$42) -> 91145.833 | E13: =PERCENTILE(Rent_Data!$J$40:$J$42,0.75) -> 109024.69 | F13: =COUNT(Rent_Data!$J$40:$J$42) -> 3 | G13: 0 | H13: 0.95 | O13: =SUMPRODUCT(I13:N13,$I$5:$N$5) -> 0 | P13: =(D13*(1+Inputs!$H$27)+G13)*Inputs!$H$21*Inputs!$H$22 -> 13671875 | Q13: =Scenarios!$F$13*H13 -> 698848500 | R13: =P13/Q13 -> 0.019563432 | S13: =Q13*Scenarios!$F$24-(Scenarios!$F$32+P13) -> 1.3759095e+08 | T13: =(Scenarios!$F$32+P13)/Scenarios!$F$24/Inputs!$H$12 -> 15374204 | U13: =0.12*Q13 -> 83861820
A16: How to read: rent stats are per m² of total building area (ruko = whole multi-storey building). Model rent = rate × usable m² × GFA factor (Inputs).
A17: Columns Q–T use the ACTIVE scenario steady-state economics (Scenarios sheet) scaled by the district demand index; only rent & service charge change by district.
A18: Occupancy cost benchmark: total rent + service charge ideally ≤ 10–12% of revenue for full-service restaurants (industry rule of thumb – verify with Jakarta operators).
A19: Upgrade path: replace demand index with a Huff gravity estimate (S40/S41) or with footfall counts at 3 comparable venues per district (Methods sheet).
A20: Filter: 100–200 m² of rented surface (all floors, any format: ruko, mall unit, single level). Senopati main road has <3 listings → rent = side streets × premium V8 until ≥3 are added (switches automatically). Kuningan n=2 – low confidence.
A23: SOURCES & CALCULATION BASIS – Location
A24: Figure / cells | D24: Value used (live) | F24: Source ID(s) → Sources sheet | I24: How the figure was derived from the source | Q24: Evidence status
A25: Rent P25 / median / P75, n (cols C–F) | D25: =Location!D9 -> 251828.12 | F25: S20–S26 via Rent_Data | I25: PERCENTILE / MEDIAN / COUNT over each district's IDR per m² of rented surface per month in Rent_Data (listings of 100–200 m²). Senopati main road: if fewer than 3 listings, side-street stats × premium V8 = 2.27 (ratio of main-road to side-street medians in the unfiltered v0.3 sample, 270.6k / 119.2k). | Q25: Derived from sources
A26: Service charge (col G) | D26: =Location!G8 -> 120000 | F26: S27; S22/S23 | I26: Street ruko = 0. SCBD 120k: podium/office F&B listings quote rent 'excl. service charge' (S23); set below the Colliers mall average of 154k (S27). Kuningan 50k = mix of ruko and mall units. Estimates. | Q26: Partly sourced
A27: Demand index (col H) | D27: =Location!H9 -> 1 | F27: S46 Volume_Proxy (in-zone velocity); S28/S29 | I27: Relative revenue potential vs Senopati = 1.0. Team judgement informed by competitor review velocity; replace with a Huff gravity estimate (S40/S41). | Q27: Assumption – validate
A28: Criteria scores (cols I–N, 1–5) | D28: — | F28: S28, S29, S46, S30 | I28: Team scoring of footfall, office density, customer fit, visibility, competition, access. Qualitative – document evidence per score after field visits. | Q28: Assumption – validate
A29: Criteria weights (I4:N4) | D29: =Location!O5 -> 1 | F29: — | I29: Team weighting (sum = 100%). | Q29: Decision / policy
A30: Est. revenue, EBITDA, break-even (cols Q–T) | D30: =Location!Q9 -> 735630000 | F30: Scenarios sheet | I30: Active-scenario steady state × demand index, with the district's own rent. | Q30: Model formula
A31: Occupancy cost % (col R) and rent cap 12% (col U) | D31: =Location!R9 -> 0.051349481 | F31: S49 (10%, ideal 6–7%); S51 (≤8–10%) | I31: Rent + SC ÷ revenue. Note the 12% cap in col U is above both benchmarks – a strict test would use 10%. | Q31: Derived from sources

Sheet Menu
A1: Menu, Pricing & Food Cost (Kasavana–Smith menu engineering)
A2: ILLUSTRATIVE placeholder menu – replace prices with your pricing decision and food costs with recipe costing from supplier quotes. Prices are NET of 10% PBJT.
A3: Note Jonas | B3: This sheets gives an idea of pricing of potential dishes and takes as source the comparisons provided by expanding Tiago's datasets (italian restaurants in Jakarta)
B4: It will be more relevant with team 1 inputs on potential menu, numbers such as COGS, popularity will be much better estimated
B5: The CORSA pricing is here to give an idea, but not definitive at all
A6: Category | B6: Item | C6: Price net (IDR) | D6: Food cost (IDR) | E6: Cost % | F6: Contribution (IDR) | G6: Units per 100 guests | H6: Revenue / 100 guests | I6: Cost / 100 guests | J6: Revenue mix | K6: Popularity in category | L6: Menu-engineering class | M6: CM × units (helper) | N6: Guest price incl. PBJT | O6: Price benchmark (source) | P6: Food-cost benchmark & check | Q6: Evidence status
A7: Pasta | B7: Cacio e pepe | C7: 89000 | D7: 24000 | E7: =D7/C7 -> 0.26966292 | F7: =C7-D7 -> 65000 | G7: 12 | H7: =C7*G7 -> 1068000 | I7: =D7*G7 -> 288000 | J7: =H7/SUM($H$7:$H$26) -> 0.10667199 | K7: =G7/SUMIF($A$7:$A$26,A7,$G$7:$G$26) -> 0.21818182 | L7: =IF(AND(F7>=SUMIF($A$7:$A$26,A7,$M$7:$M$26)/SUMIF($A$7:$A$26,A7,$G$7:$G$26),K7>=0.7/COUNTIF($A$7:$A$26,A7)),"Star",IF(K7>=0.7/COUNTIF($A$7:$A$26,A7),"Plowhorse",IF(F7>=SUMIF($A$7:$A$26,A7,$M$7:$M$26)/SUMIF($A$7:$A$26,A7,$G$7:$G$26),"Puzzle","Dog"))) -> Plowhorse | M7: =F7*G7 -> 780000 | N7: =C7*(1+Inputs!$H$17) -> 97900 | O7: S46: in-zone pasta venue medians avg ~133k (9 venues), mid-premium tier 80–165k; PBTP Blok M ~80k; S33 Pasta, Bitte! 86k, Toscana 155k | P7: Cost 27% vs S50 food 28–35%; S49 FSR max 30.3% → below range. Item cost itself = estimate, recipe costing pending. | Q7: Partly sourced
A8: Pasta | B8: Carbonara (beef bacon, halal) | C8: 98000 | D8: 30000 | E8: =D8/C8 -> 0.30612245 | F8: =C8-D8 -> 68000 | G8: 15 | H8: =C8*G8 -> 1470000 | I8: =D8*G8 -> 450000 | J8: =H8/SUM($H$7:$H$26) -> 0.14682381 | K8: =G8/SUMIF($A$7:$A$26,A8,$G$7:$G$26) -> 0.27272727 | L8: =IF(AND(F8>=SUMIF($A$7:$A$26,A8,$M$7:$M$26)/SUMIF($A$7:$A$26,A8,$G$7:$G$26),K8>=0.7/COUNTIF($A$7:$A$26,A8)),"Star",IF(K8>=0.7/COUNTIF($A$7:$A$26,A8),"Plowhorse",IF(F8>=SUMIF($A$7:$A$26,A8,$M$7:$M$26)/SUMIF($A$7:$A$26,A8,$G$7:$G$26),"Puzzle","Dog"))) -> Plowhorse | M8: =F8*G8 -> 1020000 | N8: =C8*(1+Inputs!$H$17) -> 107800 | O8: S46: in-zone pasta venue medians avg ~133k (9 venues), mid-premium tier 80–165k; PBTP Blok M ~80k; S33 Pasta, Bitte! 86k, Toscana 155k | P8: Cost 31% vs S50 food 28–35%; S49 FSR max 30.3% → within range. Item cost itself = estimate, recipe costing pending. | Q8: Partly sourced
A9: Pasta | B9: Ragù bolognese | C9: 105000 | D9: 34000 | E9: =D9/C9 -> 0.32380952 | F9: =C9-D9 -> 71000 | G9: 11 | H9: =C9*G9 -> 1155000 | I9: =D9*G9 -> 374000 | J9: =H9/SUM($H$7:$H$26) -> 0.11536157 | K9: =G9/SUMIF($A$7:$A$26,A9,$G$7:$G$26) -> 0.2 | L9: =IF(AND(F9>=SUMIF($A$7:$A$26,A9,$M$7:$M$26)/SUMIF($A$7:$A$26,A9,$G$7:$G$26),K9>=0.7/COUNTIF($A$7:$A$26,A9)),"Star",IF(K9>=0.7/COUNTIF($A$7:$A$26,A9),"Plowhorse",IF(F9>=SUMIF($A$7:$A$26,A9,$M$7:$M$26)/SUMIF($A$7:$A$26,A9,$G$7:$G$26),"Puzzle","Dog"))) -> Star | M9: =F9*G9 -> 781000 | N9: =C9*(1+Inputs!$H$17) -> 115500 | O9: S46: in-zone pasta venue medians avg ~133k (9 venues), mid-premium tier 80–165k; PBTP Blok M ~80k; S33 Pasta, Bitte! 86k, Toscana 155k | P9: Cost 32% vs S50 food 28–35%; S49 FSR max 30.3% → within range. Item cost itself = estimate, recipe costing pending. | Q9: Partly sourced
A10: Pasta | B10: Pesto genovese | C10: 95000 | D10: 28000 | E10: =D10/C10 -> 0.29473684 | F10: =C10-D10 -> 67000 | G10: 8 | H10: =C10*G10 -> 760000 | I10: =D10*G10 -> 224000 | J10: =H10/SUM($H$7:$H$26) -> 0.075908909 | K10: =G10/SUMIF($A$7:$A$26,A10,$G$7:$G$26) -> 0.14545455 | L10: =IF(AND(F10>=SUMIF($A$7:$A$26,A10,$M$7:$M$26)/SUMIF($A$7:$A$26,A10,$G$7:$G$26),K10>=0.7/COUNTIF($A$7:$A$26,A10)),"Star",IF(K10>=0.7/COUNTIF($A$7:$A$26,A10),"Plowhorse",IF(F10>=SUMIF($A$7:$A$26,A10,$M$7:$M$26)/SUMIF($A$7:$A$26,A10,$G$7:$G$26),"Puzzle","Dog"))) -> Plowhorse | M10: =F10*G10 -> 536000 | N10: =C10*(1+Inputs!$H$17) -> 104500 | O10: S46: in-zone pasta venue medians avg ~133k (9 venues), mid-premium tier 80–165k; PBTP Blok M ~80k; S33 Pasta, Bitte! 86k, Toscana 155k | P10: Cost 29% vs S50 food 28–35%; S49 FSR max 30.3% → within range. Item cost itself = estimate, recipe costing pending. | Q10: Partly sourced
A11: Pasta | B11: Truffle cream | C11: 135000 | D11: 45000 | E11: =D11/C11 -> 0.33333333 | F11: =C11-D11 -> 90000 | G11: 5 | H11: =C11*G11 -> 675000 | I11: =D11*G11 -> 225000 | J11: =H11/SUM($H$7:$H$26) -> 0.067419097 | K11: =G11/SUMIF($A$7:$A$26,A11,$G$7:$G$26) -> 0.090909091 | L11: =IF(AND(F11>=SUMIF($A$7:$A$26,A11,$M$7:$M$26)/SUMIF($A$7:$A$26,A11,$G$7:$G$26),K11>=0.7/COUNTIF($A$7:$A$26,A11)),"Star",IF(K11>=0.7/COUNTIF($A$7:$A$26,A11),"Plowhorse",IF(F11>=SUMIF($A$7:$A$26,A11,$M$7:$M$26)/SUMIF($A$7:$A$26,A11,$G$7:$G$26),"Puzzle","Dog"))) -> Puzzle | M11: =F11*G11 -> 450000 | N11: =C11*(1+Inputs!$H$17) -> 148500 | O11: S46: in-zone pasta venue medians avg ~133k (9 venues), mid-premium tier 80–165k; PBTP Blok M ~80k; S33 Pasta, Bitte! 86k, Toscana 155k | P11: Cost 33% vs S50 food 28–35%; S49 FSR max 30.3% → within range. Item cost itself = estimate, recipe costing pending. | Q11: Partly sourced
A12: Pasta | B12: Arrabbiata (vegan) | C12: 82000 | D12: 20000 | E12: =D12/C12 -> 0.24390244 | F12: =C12-D12 -> 62000 | G12: 4 | H12: =C12*G12 -> 328000 | I12: =D12*G12 -> 80000 | J12: =H12/SUM($H$7:$H$26) -> 0.032760687 | K12: =G12/SUMIF($A$7:$A$26,A12,$G$7:$G$26) -> 0.072727273 | L12: =IF(AND(F12>=SUMIF($A$7:$A$26,A12,$M$7:$M$26)/SUMIF($A$7:$A$26,A12,$G$7:$G$26),K12>=0.7/COUNTIF($A$7:$A$26,A12)),"Star",IF(K12>=0.7/COUNTIF($A$7:$A$26,A12),"Plowhorse",IF(F12>=SUMIF($A$7:$A$26,A12,$M$7:$M$26)/SUMIF($A$7:$A$26,A12,$G$7:$G$26),"Puzzle","Dog"))) -> Dog | M12: =F12*G12 -> 248000 | N12: =C12*(1+Inputs!$H$17) -> 90200 | O12: S46: in-zone pasta venue medians avg ~133k (9 venues), mid-premium tier 80–165k; PBTP Blok M ~80k; S33 Pasta, Bitte! 86k, Toscana 155k | P12: Cost 24% vs S50 food 28–35%; S49 FSR max 30.3% → below range. Item cost itself = estimate, recipe costing pending. | Q12: Partly sourced
A13: Coffee | B13: Espresso | C13: 32000 | D13: 6000 | E13: =D13/C13 -> 0.1875 | F13: =C13-D13 -> 26000 | G13: 5 | H13: =C13*G13 -> 160000 | I13: =D13*G13 -> 30000 | J13: =H13/SUM($H$7:$H$26) -> 0.015980823 | K13: =G13/SUMIF($A$7:$A$26,A13,$G$7:$G$26) -> 0.1 | L13: =IF(AND(F13>=SUMIF($A$7:$A$26,A13,$M$7:$M$26)/SUMIF($A$7:$A$26,A13,$G$7:$G$26),K13>=0.7/COUNTIF($A$7:$A$26,A13)),"Star",IF(K13>=0.7/COUNTIF($A$7:$A$26,A13),"Plowhorse",IF(F13>=SUMIF($A$7:$A$26,A13,$M$7:$M$26)/SUMIF($A$7:$A$26,A13,$G$7:$G$26),"Puzzle","Dog"))) -> Dog | M13: =F13*G13 -> 130000 | N13: =C13*(1+Inputs!$H$17) -> 35200 | O13: S31: Common Grounds espresso 32k (= model price) | P13: Cost 19% vs S49 coffee bev. cost 15–20%; S50 beverage 15–25% → within range. Item cost itself = estimate, recipe costing pending. | Q13: Partly sourced
A14: Coffee | B14: Americano (hot/iced) | C14: 40000 | D14: 7000 | E14: =D14/C14 -> 0.175 | F14: =C14-D14 -> 33000 | G14: 12 | H14: =C14*G14 -> 480000 | I14: =D14*G14 -> 84000 | J14: =H14/SUM($H$7:$H$26) -> 0.047942469 | K14: =G14/SUMIF($A$7:$A$26,A14,$G$7:$G$26) -> 0.24 | L14: =IF(AND(F14>=SUMIF($A$7:$A$26,A14,$M$7:$M$26)/SUMIF($A$7:$A$26,A14,$G$7:$G$26),K14>=0.7/COUNTIF($A$7:$A$26,A14)),"Star",IF(K14>=0.7/COUNTIF($A$7:$A$26,A14),"Plowhorse",IF(F14>=SUMIF($A$7:$A$26,A14,$M$7:$M$26)/SUMIF($A$7:$A$26,A14,$G$7:$G$26),"Puzzle","Dog"))) -> Plowhorse | M14: =F14*G14 -> 396000 | N14: =C14*(1+Inputs!$H$17) -> 44000 | O14: S46: latte 27–30k casual, 38–48k smart-casual/specialty, 55–60k mall; S31 Common Grounds latte 45–52k, espresso 32k | P14: Cost 18% vs S49 coffee bev. cost 15–20%; S50 beverage 15–25% → within range. Item cost itself = estimate, recipe costing pending. | Q14: Partly sourced
A15: Coffee | B15: Latte / flat white | C15: 50000 | D15: 12000 | E15: =D15/C15 -> 0.24 | F15: =C15-D15 -> 38000 | G15: 19 | H15: =C15*G15 -> 950000 | I15: =D15*G15 -> 228000 | J15: =H15/SUM($H$7:$H$26) -> 0.094886137 | K15: =G15/SUMIF($A$7:$A$26,A15,$G$7:$G$26) -> 0.38 | L15: =IF(AND(F15>=SUMIF($A$7:$A$26,A15,$M$7:$M$26)/SUMIF($A$7:$A$26,A15,$G$7:$G$26),K15>=0.7/COUNTIF($A$7:$A$26,A15)),"Star",IF(K15>=0.7/COUNTIF($A$7:$A$26,A15),"Plowhorse",IF(F15>=SUMIF($A$7:$A$26,A15,$M$7:$M$26)/SUMIF($A$7:$A$26,A15,$G$7:$G$26),"Puzzle","Dog"))) -> Star | M15: =F15*G15 -> 722000 | N15: =C15*(1+Inputs!$H$17) -> 55000 | O15: S46: latte 27–30k casual, 38–48k smart-casual/specialty, 55–60k mall; S31 Common Grounds latte 45–52k, espresso 32k | P15: Cost 24% vs S49 coffee bev. cost 15–20%; S50 beverage 15–25% → within range. Item cost itself = estimate, recipe costing pending. | Q15: Partly sourced
A16: Coffee | B16: Signature iced coffee | C16: 58000 | D16: 14000 | E16: =D16/C16 -> 0.24137931 | F16: =C16-D16 -> 44000 | G16: 10 | H16: =C16*G16 -> 580000 | I16: =D16*G16 -> 140000 | J16: =H16/SUM($H$7:$H$26) -> 0.057930483 | K16: =G16/SUMIF($A$7:$A$26,A16,$G$7:$G$26) -> 0.2 | L16: =IF(AND(F16>=SUMIF($A$7:$A$26,A16,$M$7:$M$26)/SUMIF($A$7:$A$26,A16,$G$7:$G$26),K16>=0.7/COUNTIF($A$7:$A$26,A16)),"Star",IF(K16>=0.7/COUNTIF($A$7:$A$26,A16),"Plowhorse",IF(F16>=SUMIF($A$7:$A$26,A16,$M$7:$M$26)/SUMIF($A$7:$A$26,A16,$G$7:$G$26),"Puzzle","Dog"))) -> Star | M16: =F16*G16 -> 440000 | N16: =C16*(1+Inputs!$H$17) -> 63800 | O16: S46: latte 27–30k casual, 38–48k smart-casual/specialty, 55–60k mall; S31 Common Grounds latte 45–52k, espresso 32k | P16: Cost 24% vs S49 coffee bev. cost 15–20%; S50 beverage 15–25% → within range. Item cost itself = estimate, recipe costing pending. | Q16: Partly sourced
